Workbook
Name Coal_trade: #REF!
Name Fuels: #REF!
Name gasdemand: #REF!
Name INDIC_T6_APS: #REF!
Name INDIC_T6_NZE: #REF!
Name INDIC_T6_STEPS: #REF!
Name IQ_CH: 110000
Name IQ_CQ: 5000
Name IQ_CY: 10000
Name IQ_DAILY: 500000
Name IQ_FH: 100000
Name IQ_FQ: 500
Name IQ_FWD_CY: 10001
Name IQ_FWD_CY1: 10002
Name IQ_FWD_CY2: 10003
Name IQ_FWD_FY: 1001

Sheet NOUSELCOE_Expand_toAPS
B1: CAPEX-Large | C1: ANM-Large | E1: CAPEX-rooftop | F1: ANM-rooftop | K1: This spreadsheet contains the derived ANM rather than
B3: 2023 | C3: 2023 | E3: 2023 | F3: 2023 | K3: Update 2023
A5: European Union | B5: =L5 -> 750 | C5: =M5 -> 12 | E5: =O5 -> 990 | F5: =P5 -> 14 | K5: European Union | L5: 750 | M5: 12 | O5: 990 | P5: 14
A6: United States | B6: =L6 -> 1110 | C6: =M6 -> 16 | E6: =O6 -> 3460 | F6: =P6 -> 52 | K6: United States | L6: 1110 | M6: 16 | O6: 3460 | P6: 52
A7: Japan | B7: =L7 -> 1880 | C7: =M7 -> 28 | E7: =O7 -> 1850 | F7: =P7 -> 28 | K7: Japan | L7: 1880 | M7: 28 | O7: 1850 | P7: 28
A8: Russia | B8: =L8 -> 1250 | C8: =M8 -> 18 | E8: =O8 -> 1610 | F8: =P8 -> 24 | K8: Russia | L8: 1250 | M8: 18 | O8: 1610 | P8: 24
A9: China | B9: =L9 -> 670 | C9: =M9 -> 12 | E9: =O9 -> 750 | F9: =P9 -> 14 | K9: China | L9: 670 | M9: 12 | O9: 750 | P9: 14
A10: India | B10: =L10 -> 710 | C10: =M10 -> 10 | E10: =O10 -> 780 | F10: =P10 -> 12 | K10: India | L10: 710 | M10: 10 | O10: 780 | P10: 12
A11: Middle East | B11: =L11 -> 610 | C11: =M11 -> 10 | E11: =O11 -> 1010 | F11: =P11 -> 16 | K11: Middle East | L11: 610 | M11: 10 | O11: 1010 | P11: 16
A12: Africa | B12: =L12 -> 1330 | C12: =M12 -> 20 | E12: =O12 -> 1830 | F12: =P12 -> 28 | K12: Africa | L12: 1330 | M12: 20 | O12: 1830 | P12: 28
A13: Brazil | B13: =L13 -> 730 | C13: =M13 -> 10 | E13: =O13 -> 560 | F13: =P13 -> 8 | K13: Brazil | L13: 730 | M13: 10 | O13: 560 | P13: 8
B15: PV capacity | C15: PV capacity | E15: PV capacity | F15: PV capacity
B16: 2023 | C16: 2023 | E16: 2023 | F16: 2023
A17: European Union | B17: ='Summari-ForCount (2030)'!AO60 -> 266.93 | C17: =B17 -> 266.93 | E17: =B17 -> 266.93 | F17: =C17 -> 266.93
A18: United States | B18: ='Summari-ForCount (2030)'!AO62 -> 169.75 | C18: =B18 -> 169.75 | E18: =B18 -> 169.75 | F18: =C18 -> 169.75
A19: Japan | B19: ='Summari-ForCount (2030)'!AO66 -> 108.16 | C19: =B19 -> 108.16 | E19: =B19 -> 108.16 | F19: =C19 -> 108.16
A20: Russia | B20: ='Summari-ForCount (2030)'!AO63 -> 2.13 | C20: =B20 -> 2.13 | E20: =B20 -> 2.13 | F20: =C20 -> 2.13
A21: China | B21: ='Summari-ForCount (2030)'!AO64 -> 688.24 | C21: =B21 -> 688.24 | E21: =B21 -> 688.24 | F21: =C21 -> 688.24
A22: India | B22: ='Summari-ForCount (2030)'!AO65 -> 94.77 | C22: =B22 -> 94.77 | E22: =B22 -> 94.77 | F22: =C22 -> 94.77
A23: Middle East | B23: ='Summarize-ForReg(Current&2050)'!AL65 -> 13.85 | C23: =B23 -> 13.85 | E23: =B23 -> 13.85 | F23: =C23 -> 13.85
A24: Africa | B24: ='Summarize-ForReg(Current&2050)'!AL66 -> 17.04 | C24: =B24 -> 17.04 | E24: =B24 -> 17.04 | F24: =C24 -> 17.04
A25: Brazil | B25: ='Summari-ForCount (2030)'!AO61 -> 41.48 | C25: =B25 -> 41.48 | E25: =B25 -> 41.48 | F25: =C25 -> 41.48
K26: CAPEX-Large | L26: ANM-Large | N26: CAPEX-rooftop | O26: ANM-rooftop | S26: Which input to LCOE calculation code
B27: PV capacity | C27: PV capacity | E27: PV capacity | F27: PV capacity | S27: CAPEX-Large | V27: OM-Large | Y27: CAPEX-Rooftop | AB27: OM-Rooftop
B28: APS-2030 | C28: 2030 | E28: 2030 | F28: 2030 | K28: APS-2030 | L28: 2030 | N28: 2030 | O28: 2030 | S28: =K28 -> APS-2030 | T28: =K40 -> APS-2050 | V28: =N28 -> 2030 | W28: =N40 -> 2050
A29: European Union | B29: ='Summari-ForCount (2030)'!AR60 -> 746.62 | C29: =B29 -> 746.62 | E29: =B29 -> 746.62 | F29: =C29 -> 746.62 | J29: European Union | K29: =B5*(0.8)^(LOG((B29/B17),2)) -> 538.58625 | L29: =C5*(0.8)^(LOG((C29/C17),2)) -> 8.6173801 | N29: =E5*(0.8)^(LOG((E29/E17),2)) -> 710.93385 | O29: =F5*(0.8)^(LOG((F29/F17),2)) -> 10.05361 | R29: European Union | S29: =K29 -> 538.58625 | T29: =K41 -> 476.6209 | V29: =L29 -> 8.6173801 | W29: =L41 -> 7.6259345 | Y29: =N29 -> 710.93385 | Z29: =N41 -> 629.13959 | AB29: =O29 -> 10.05361 | AC29: =O41 -> 8.8969235
A30: United States | B30: ='Summari-ForCount (2030)'!AR62 -> 719.52 | C30: =B30 -> 719.52 | E30: =B30 -> 719.52 | F30: =C30 -> 719.52 | J30: United States | K30: =B6*(0.8)^(LOG((B30/B18),2)) -> 697.26686 | L30: =C6*(0.8)^(LOG((C30/C18),2)) -> 10.050694 | N30: =E6*(0.8)^(LOG((E30/E18),2)) -> 2173.4625 | O30: =F6*(0.8)^(LOG((F30/F18),2)) -> 32.664754 | R30: United States | S30: =K30 -> 697.26686 | T30: =K42 -> 497.13653 | V30: =L30 -> 10.050694 | W30: =L42 -> 7.1659319 | Y30: =N30 -> 2173.4625 | Z30: =N42 -> 1549.6328 | AB30: =O30 -> 32.664754 | AC30: =O42 -> 23.289279
A31: Japan | B31: ='Summari-ForCount (2030)'!AR66 -> 172.08 | C31: =B31 -> 172.08 | E31: =B31 -> 172.08 | F31: =C31 -> 172.08 | J31: Japan | K31: =B7*(0.8)^(LOG((B31/B19),2)) -> 1618.9619 | L31: =C7*(0.8)^(LOG((C31/C19),2)) -> 24.112199 | N31: =E7*(0.8)^(LOG((E31/E19),2)) -> 1593.1274 | O31: =F7*(0.8)^(LOG((F31/F19),2)) -> 24.112199 | R31: Japan | S31: =K31 -> 1618.9619 | T31: =K43 -> 1490.6173 | V31: =L31 -> 24.112199 | W31: =L43 -> 22.200683 | Y31: =N31 -> 1593.1274 | Z31: =N43 -> 1466.8308 | AB31: =O31 -> 24.112199 | AC31: =O43 -> 22.200683
A32: Russia | B32: ='Summari-ForCount (2030)'!AR63 -> 5.49 | C32: =B32 -> 5.49 | E32: =B32 -> 5.49 | F32: =C32 -> 5.49 | J32: Russia | K32: =B8*(0.8)^(LOG((B32/B20),2)) -> 921.58525 | L32: =C8*(0.8)^(LOG((C32/C20),2)) -> 13.270828 | N32: =E8*(0.8)^(LOG((E32/E20),2)) -> 1187.0018 | O32: =F8*(0.8)^(LOG((F32/F20),2)) -> 17.694437 | R32: Russia | S32: =K32 -> 921.58525 | T32: =K44 -> 609.11356 | V32: =L32 -> 13.270828 | W32: =L44 -> 8.7712352 | Y32: =N32 -> 1187.0018 | Z32: =N44 -> 784.53826 | AB32: =O32 -> 17.694437 | AC32: =O44 -> 11.69498
A33: China | B33: ='Summari-ForCount (2030)'!AR64 -> 3315.59 | C33: =B33 -> 3315.59 | E33: =B33 -> 3315.59 | F33: =C33 -> 3315.59 | J33: China | K33: =B9*(0.8)^(LOG((B33/B21),2)) -> 403.88299 | L33: =C9*(0.8)^(LOG((C33/C21),2)) -> 7.2337253 | N33: =E9*(0.8)^(LOG((E33/E21),2)) -> 452.10783 | O33: =F9*(0.8)^(LOG((F33/F21),2)) -> 8.4393462 | R33: China | S33: =K33 -> 403.88299 | T33: =K45 -> 286.84943 | V33: =L33 -> 7.2337253 | W33: =L45 -> 5.1376017 | Y33: =N33 -> 452.10783 | Z33: =N45 -> 321.10011 | AB33: =O33 -> 8.4393462 | AC33: =O45 -> 5.9938687
A34: India | B34: ='Summari-ForCount (2030)'!AR65 -> 385.32 | C34: =B34 -> 385.32 | E34: =B34 -> 385.32 | F34: =C34 -> 385.32 | J34: India | K34: =B10*(0.8)^(LOG((B34/B22),2)) -> 452.0179 | L34: =C10*(0.8)^(LOG((C34/C22),2)) -> 6.3664493 | N34: =E10*(0.8)^(LOG((E34/E22),2)) -> 496.58305 | O34: =F10*(0.8)^(LOG((F34/F22),2)) -> 7.6397392 | R34: India | S34: =K34 -> 452.0179 | T34: =K46 -> 271.25563 | V34: =L34 -> 6.3664493 | W34: =L46 -> 3.8205018 | Y34: =N34 -> 496.58305 | Z34: =N46 -> 297.99914 | AB34: =O34 -> 7.6397392 | AC34: =O46 -> 4.5846022
A35: Middle East | B35: ='Summarize-ForReg(2030)'!AP65 -> 132.56 | C35: =B35 -> 132.56 | E35: =B35 -> 132.56 | F35: =C35 -> 132.56 | J35: Middle East | K35: =B11*(0.8)^(LOG((B35/B23),2)) -> 294.80197 | L35: =C11*(0.8)^(LOG((C35/C23),2)) -> 4.8328191 | N35: =E11*(0.8)^(LOG((E35/E23),2)) -> 488.11473 | O35: =F11*(0.8)^(LOG((F35/F23),2)) -> 7.7325106 | R35: Middle East | S35: =K35 -> 294.80197 | T35: =K47 -> 152.44005 | V35: =L35 -> 4.8328191 | W35: =L47 -> 2.4990171 | Y35: =N35 -> 488.11473 | Z35: =N47 -> 252.40073 | AB35: =O35 -> 7.7325106 | AC35: =O47 -> 3.9984274
A36: Africa | B36: ='Summarize-ForReg(2030)'!AP66 -> 175.19 | C36: =B36 -> 175.19 | E36: =B36 -> 175.19 | F36: =C36 -> 175.19 | J36: Africa | K36: =B12*(0.8)^(LOG((B36/B24),2)) -> 628.12723 | L36: =C12*(0.8)^(LOG((C36/C24),2)) -> 9.4455223 | N36: =E12*(0.8)^(LOG((E36/E24),2)) -> 864.26529 | O36: =F12*(0.8)^(LOG((F36/F24),2)) -> 13.223731 | R36: Africa | S36: =K36 -> 628.12723 | T36: =K48 -> 365.0569 | V36: =L36 -> 9.4455223 | W36: =L48 -> 5.4895774 | Y36: =N36 -> 864.26529 | Z36: =N48 -> 502.29634 | AB36: =O36 -> 13.223731 | AC36: =O48 -> 7.6854084
A37: Brazil | B37: ='Summari-ForCount (2030)'!AR61 -> 135.34 | C37: =B37 -> 135.34 | E37: =B37 -> 135.34 | F37: =C37 -> 135.34 | J37: Brazil | K37: =B13*(0.8)^(LOG((B37/B25),2)) -> 498.86684 | L37: =C13*(0.8)^(LOG((C37/C25),2)) -> 6.8337924 | N37: =E13*(0.8)^(LOG((E37/E25),2)) -> 382.69237 | O37: =F13*(0.8)^(LOG((F37/F25),2)) -> 5.4670339 | R37: Brazil | S37: =K37 -> 498.86684 | T37: =K49 -> 411.63787 | V37: =L37 -> 6.8337924 | W37: =L49 -> 5.638875 | Y37: =N37 -> 382.69237 | Z37: =N49 -> 315.777 | AB37: =O37 -> 5.4670339 | AC37: =O49 -> 4.5111
B39: PV capacity | C39: PV capacity | E39: PV capacity | F39: PV capacity
B40: APS-2050 | C40: 2050 | E40: 2050 | F40: 2050 | K40: APS-2050 | L40: 2050 | N40: 2050 | O40: 2050
A41: European Union | B41: ='Summari-ForCount (Current&2050)'!AB95 -> 1091.41 | C41: =B41 -> 1091.41 | E41: =B41 -> 1091.41 | F41: =C41 -> 1091.41 | K41: =B5*(0.8)^(LOG((B41/B17),2)) -> 476.6209 | L41: =C5*(0.8)^(LOG((C41/C17),2)) -> 7.6259345 | N41: =E5*(0.8)^(LOG((E41/E17),2)) -> 629.13959 | O41: =F5*(0.8)^(LOG((F41/F17),2)) -> 8.8969235
A42: United States | B42: ='Summari-ForCount (Current&2050)'!AB97 -> 2057.92 | C42: =B42 -> 2057.92 | E42: =B42 -> 2057.92 | F42: =C42 -> 2057.92 | K42: =B6*(0.8)^(LOG((B42/B18),2)) -> 497.13653 | L42: =C6*(0.8)^(LOG((C42/C18),2)) -> 7.1659319 | N42: =E6*(0.8)^(LOG((E42/E18),2)) -> 1549.6328 | O42: =F6*(0.8)^(LOG((F42/F18),2)) -> 23.289279
A43: Japan | B43: ='Summari-ForCount (Current&2050)'!AB101 -> 222.41 | C43: =B43 -> 222.41 | E43: =B43 -> 222.41 | F43: =C43 -> 222.41 | K43: =B7*(0.8)^(LOG((B43/B19),2)) -> 1490.6173 | L43: =C7*(0.8)^(LOG((C43/C19),2)) -> 22.200683 | N43: =E7*(0.8)^(LOG((E43/E19),2)) -> 1466.8308 | O43: =F7*(0.8)^(LOG((F43/F19),2)) -> 22.200683
A44: Russia | B44: ='Summari-ForCount (Current&2050)'!AB98 -> 19.87 | C44: =B44 -> 19.87 | E44: =B44 -> 19.87 | F44: =C44 -> 19.87 | K44: =B8*(0.8)^(LOG((B44/B20),2)) -> 609.11356 | L44: =C8*(0.8)^(LOG((C44/C20),2)) -> 8.7712352 | N44: =E8*(0.8)^(LOG((E44/E20),2)) -> 784.53826 | O44: =F8*(0.8)^(LOG((F44/F20),2)) -> 11.69498
...

Sheet NOUSE
B1: CAPEX-Large | C1: ANM-Large | E1: CAPEX-rooftop | F1: ANM-rooftop | K1: This spreadsheet contains the NZE_ ANM rather than | U1: Annual O&M Costs (USD/kW)
B3: 2022 | C3: 2022 | E3: 2022 | F3: 2022 | U3: 2030 | V3: 2050
A5: European Union | B5: 990 | C5: 14 | E5: 1320 | F5: 20 | T5: Large | U5: 14 | V5: 12
A6: United States | B6: 1120 | C6: 16 | E6: 3490 | F6: 52 | U6: 16 | V6: 16
A7: Japan | B7: 1910 | C7: 28 | E7: 1880 | F7: 28 | U7: 24 | V7: 22
A8: Russia | B8: 1710 | C8: 26 | E8: 2210 | F8: 34 | U8: 22 | V8: 22
A9: China | B9: 720 | C9: 12 | E9: 800 | F9: 14 | U9: 10 | V9: 10
A10: India | B10: 640 | C10: 10 | E10: 700 | F10: 10 | U10: 8 | V10: 8
A11: Middle East | B11: 620 | C11: 10 | E11: 1020 | F11: 16 | U11: 8 | V11: 8
A12: Africa | B12: 1420 | C12: 22 | E12: 1970 | F12: 30 | U12: 18 | V12: 18
A13: Brazil | B13: 750 | C13: 12 | E13: 580 | F13: 8 | U13: 10 | V13: 10
B15: PV capacity | C15: PV capacity | E15: PV capacity | F15: PV capacity | T15: Rooftop | U15: 18 | V15: 14
B16: 2022 | C16: 2022 | E16: 2022 | F16: 2022 | U16: 46 | V16: 44
A17: European Union | B17: ='Summari-ForCount (2030)'!AO60 -> 266.93 | C17: =B17 -> 266.93 | E17: =B17 -> 266.93 | F17: =C17 -> 266.93 | U17: 24 | V17: 22
A18: United States | B18: ='Summari-ForCount (2030)'!AO62 -> 169.75 | C18: =B18 -> 169.75 | E18: =B18 -> 169.75 | F18: =C18 -> 169.75 | U18: 30 | V18: 28
A19: Japan | B19: ='Summari-ForCount (2030)'!AO66 -> 108.16 | C19: =B19 -> 108.16 | E19: =B19 -> 108.16 | F19: =C19 -> 108.16 | U19: 10 | V19: 10
A20: Russia | B20: ='Summari-ForCount (2030)'!AO63 -> 2.13 | C20: =B20 -> 2.13 | E20: =B20 -> 2.13 | F20: =C20 -> 2.13 | U20: 10 | V20: 8
A21: China | B21: ='Summari-ForCount (2030)'!AO64 -> 688.24 | C21: =B21 -> 688.24 | E21: =B21 -> 688.24 | F21: =C21 -> 688.24 | U21: 14 | V21: 12
A22: India | B22: ='Summari-ForCount (2030)'!AO65 -> 94.77 | C22: =B22 -> 94.77 | E22: =B22 -> 94.77 | F22: =C22 -> 94.77 | U22: 26 | V22: 24
A23: Middle East | B23: ='Summarize-ForReg(Current&2050)'!AL65 -> 13.85 | C23: =B23 -> 13.85 | E23: =B23 -> 13.85 | F23: =C23 -> 13.85 | U23: 8 | V23: 8
A24: Africa | B24: ='Summarize-ForReg(Current&2050)'!AL66 -> 17.04 | C24: =B24 -> 17.04 | E24: =B24 -> 17.04 | F24: =C24 -> 17.04
A25: Brazil | B25: ='Summari-ForCount (2030)'!AO61 -> 41.48 | C25: =B25 -> 41.48 | E25: =B25 -> 41.48 | F25: =C25 -> 41.48
K26: CAPEX-Large | L26: ANM-Large | N26: CAPEX-rooftop | O26: ANM-rooftop | S26: Which input to LCOE calculation code
B27: PV capacity | C27: PV capacity | E27: PV capacity | F27: PV capacity | S27: CAPEX-Large | V27: OM-Large | Y27: CAPEX-Rooftop | AB27: OM-Rooftop
B28: APS-2030 | C28: 2030 | E28: 2030 | F28: 2030 | K28: APS-2030 | L28: 2030 | N28: 2030 | O28: 2030 | S28: =K28 -> APS-2030 | T28: =K40 -> APS-2050 | V28: =N28 -> 2030 | W28: =N40 -> 2050
A29: European Union | B29: ='Summari-ForCount (2030)'!AR60 -> 746.62 | C29: =B29 -> 746.62 | E29: =B29 -> 746.62 | F29: =C29 -> 746.62 | K29: =B5*(0.8)^(LOG((B29/B17),2)) -> 710.93385 | L29: 14 | N29: =E5*(0.8)^(LOG((E29/E17),2)) -> 947.91181 | O29: 18 | R29: European Union | S29: =K29 -> 710.93385 | T29: =K41 -> 629.13959 | V29: =L29 -> 14 | W29: =L41 -> 12 | Y29: =N29 -> 947.91181 | Z29: =N41 -> 838.85279 | AB29: =O29 -> 18 | AC29: =O41 -> 14
A30: United States | B30: ='Summari-ForCount (2030)'!AR62 -> 719.52 | C30: =B30 -> 719.52 | E30: =B30 -> 719.52 | F30: =C30 -> 719.52 | K30: =B6*(0.8)^(LOG((B30/B18),2)) -> 703.54855 | L30: 16 | N30: =E6*(0.8)^(LOG((E30/E18),2)) -> 2192.3075 | O30: 46 | R30: United States | S30: =K30 -> 703.54855 | T30: =K42 -> 501.61523 | V30: =L30 -> 16 | W30: =L42 -> 16 | Y30: =N30 -> 2192.3075 | Z30: =N42 -> 1563.0689 | AB30: =O30 -> 46 | AC30: =O42 -> 44
A31: Japan | B31: ='Summari-ForCount (2030)'!AR66 -> 172.08 | C31: =B31 -> 172.08 | E31: =B31 -> 172.08 | F31: =C31 -> 172.08 | K31: =B7*(0.8)^(LOG((B31/B19),2)) -> 1644.7964 | L31: 24 | N31: =E7*(0.8)^(LOG((E31/E19),2)) -> 1618.9619 | O31: 24 | R31: Japan | S31: =K31 -> 1644.7964 | T31: =K43 -> 1514.4037 | V31: =L31 -> 24 | W31: =L43 -> 22 | Y31: =N31 -> 1618.9619 | Z31: =N43 -> 1490.6173 | AB31: =O31 -> 24 | AC31: =O43 -> 22
A32: Russia | B32: ='Summari-ForCount (2030)'!AR63 -> 5.49 | C32: =B32 -> 5.49 | E32: =B32 -> 5.49 | F32: =C32 -> 5.49 | K32: =B8*(0.8)^(LOG((B32/B20),2)) -> 1260.7286 | L32: 22 | N32: =E8*(0.8)^(LOG((E32/E20),2)) -> 1629.3627 | O32: 30 | R32: Russia | S32: =K32 -> 1260.7286 | T32: =K44 -> 833.26735 | V32: =L32 -> 22 | W32: =L44 -> 22 | Y32: =N32 -> 1629.3627 | Z32: =N44 -> 1076.9128 | AB32: =O32 -> 30 | AC32: =O44 -> 28
A33: China | B33: ='Summari-ForCount (2030)'!AR64 -> 3315.59 | C33: =B33 -> 3315.59 | E33: =B33 -> 3315.59 | F33: =C33 -> 3315.59 | K33: =B9*(0.8)^(LOG((B33/B21),2)) -> 434.02352 | L33: 10 | N33: =E9*(0.8)^(LOG((E33/E21),2)) -> 482.24835 | O33: 10 | R33: China | S33: =K33 -> 434.02352 | T33: =K45 -> 308.2561 | V33: =L33 -> 10 | W33: =L45 -> 10 | Y33: =N33 -> 482.24835 | Z33: =N45 -> 342.50678 | AB33: =O33 -> 10 | AC33: =O45 -> 10
A34: India | B34: ='Summari-ForCount (2030)'!AR65 -> 385.32 | C34: =B34 -> 385.32 | E34: =B34 -> 385.32 | F34: =C34 -> 385.32 | K34: =B10*(0.8)^(LOG((B34/B22),2)) -> 407.45276 | L34: 8 | N34: =E10*(0.8)^(LOG((E34/E22),2)) -> 445.65145 | O34: 10 | R34: India | S34: =K34 -> 407.45276 | T34: =K46 -> 244.51212 | V34: =L34 -> 8 | W34: =L46 -> 8 | Y34: =N34 -> 445.65145 | Z34: =N46 -> 267.43513 | AB34: =O34 -> 10 | AC34: =O46 -> 8
A35: Middle East | B35: ='Summarize-ForReg(2030)'!AP65 -> 132.56 | C35: =B35 -> 132.56 | E35: =B35 -> 132.56 | F35: =C35 -> 132.56 | K35: =B11*(0.8)^(LOG((B35/B23),2)) -> 299.63478 | L35: 8 | N35: =E11*(0.8)^(LOG((E35/E23),2)) -> 492.94755 | O35: 14 | R35: Middle East | S35: =K35 -> 299.63478 | T35: =K47 -> 154.93906 | V35: =L35 -> 8 | W35: =L47 -> 8 | Y35: =N35 -> 492.94755 | Z35: =N47 -> 254.89975 | AB35: =O35 -> 14 | AC35: =O47 -> 12
A36: Africa | B36: ='Summarize-ForReg(2030)'!AP66 -> 175.19 | C36: =B36 -> 175.19 | E36: =B36 -> 175.19 | F36: =C36 -> 175.19 | K36: =B12*(0.8)^(LOG((B36/B24),2)) -> 670.63208 | L36: 18 | N36: =E12*(0.8)^(LOG((E36/E24),2)) -> 930.38394 | O36: 26 | R36: Africa | S36: =K36 -> 670.63208 | T36: =K48 -> 389.76 | V36: =L36 -> 18 | W36: =L48 -> 18 | Y36: =N36 -> 930.38394 | Z36: =N48 -> 540.72338 | AB36: =O36 -> 26 | AC36: =O48 -> 24
A37: Brazil | B37: ='Summari-ForCount (2030)'!AR61 -> 135.34 | C37: =B37 -> 135.34 | E37: =B37 -> 135.34 | F37: =C37 -> 135.34 | K37: =B13*(0.8)^(LOG((B37/B25),2)) -> 512.53443 | L37: 10 | N37: =E13*(0.8)^(LOG((E37/E25),2)) -> 396.35996 | O37: 8 | R37: Brazil | S37: =K37 -> 512.53443 | T37: =K49 -> 422.91562 | V37: =L37 -> 10 | W37: =L49 -> 10 | Y37: =N37 -> 396.35996 | Z37: =N49 -> 327.05475 | AB37: =O37 -> 8 | AC37: =O49 -> 8
B39: PV capacity | C39: PV capacity | E39: PV capacity | F39: PV capacity
B40: APS-2050 | C40: 2050 | E40: 2050 | F40: 2050 | K40: APS-2050 | L40: 2050 | N40: 2050 | O40: 2050
A41: European Union | B41: ='Summari-ForCount (Current&2050)'!AB95 -> 1091.41 | C41: =B41 -> 1091.41 | E41: =B41 -> 1091.41 | F41: =C41 -> 1091.41 | K41: =B5*(0.8)^(LOG((B41/B17),2)) -> 629.13959 | L41: 12 | N41: =E5*(0.8)^(LOG((E41/E17),2)) -> 838.85279 | O41: 14
A42: United States | B42: ='Summari-ForCount (Current&2050)'!AB97 -> 2057.92 | C42: =B42 -> 2057.92 | E42: =B42 -> 2057.92 | F42: =C42 -> 2057.92 | K42: =B6*(0.8)^(LOG((B42/B18),2)) -> 501.61523 | L42: 16 | N42: =E6*(0.8)^(LOG((E42/E18),2)) -> 1563.0689 | O42: 44
A43: Japan | B43: ='Summari-ForCount (Current&2050)'!AB101 -> 222.41 | C43: =B43 -> 222.41 | E43: =B43 -> 222.41 | F43: =C43 -> 222.41 | K43: =B7*(0.8)^(LOG((B43/B19),2)) -> 1514.4037 | L43: 22 | N43: =E7*(0.8)^(LOG((E43/E19),2)) -> 1490.6173 | O43: 22
A44: Russia | B44: ='Summari-ForCount (Current&2050)'!AB98 -> 19.87 | C44: =B44 -> 19.87 | E44: =B44 -> 19.87 | F44: =C44 -> 19.87 | K44: =B8*(0.8)^(LOG((B44/B20),2)) -> 833.26735 | L44: 22 | N44: =E8*(0.8)^(LOG((E44/E20),2)) -> 1076.9128 | O44: 28
...

Sheet Summari-ForCount (2030)
A1: *Priciple: Exclusive the duplicate records from WEO, IEA2020, IRENA from Data of Brief; Use the record of now (preferring latest year); if there are multiple records in a same reference (except those notifying maximum or minimum value), average them to represent the figure for this reference
F3: WEO2024 (large, ground-mounted) | G3: WEO2024 (rooftop) | H3: IRENA2024 (large, ground-mounted) | I3: IEA2020 (large, ground-mounted, 3% disc-rate) | J3: IEA2020 (large, ground-mounted, 7% discount rate) | K3: IEA2020 (large, ground-mounted, 10% discount rate) | L3: IEA2020 (rooftop, 3% disc-rate) | M3: IEA2020 (rooftop, 7% discount rate) | N3: IEA2020 (rooftop, 10% discount rate) | O3: Hatton et al., 2024 (large, ground-mounted) | V3: USA
D4: Europe | E4: EU-27 | F4: =Attached_WEO2023!B12 -> 750 | G4: =Attached_WEO2023!F12 -> 990 | O4: =AVERAGE('Attached-DIB_GNESTE_Solar_Power'!W70:W74) -> 860.90269 | X4: Stated Policies (STEPS) | AD4: Announced Pledges (APS)
E5: Greece | H5: ='Attached-IRENA2024 report'!J20 -> 626.34564 | V5: 2023 | X5: 2030 | Y5: 2035 | Z5: 2040 | AA5: 2045 | AB5: 2050 | AD5: 2030 | AE5: 2035 | AF5: 2040 | AG5: 2045 | AH5: 2050
E6: Netherlands | H6: ='Attached-IRENA2024 report'!J22 -> 753.19994 | I6: ='Attached-IEA2020Projected Costs'!K39 -> 819.39997 | J6: ='Attached-IEA2020Projected Costs'!L39 -> 835.15911 | K6: ='Attached-IEA2020Projected Costs'!M39 -> 846.78601 | L6: ='Attached-IEA2020Projected Costs'!K38 -> 858.48319 | M6: ='Attached-IEA2020Projected Costs'!L38 -> 874.994 | N6: ='Attached-IEA2020Projected Costs'!M38 -> 887.17547 | O6: =AVERAGE('Attached-DIB_GNESTE_Solar_Power'!V66:V68) -> 787.41448 | V6: 169.75 | X6: 563.37 | Y6: 912.72 | Z6: 1278.24 | AA6: 1626.29 | AB6: 1894.82 | AD6: 719.52 | AE6: 1210.5 | AF6: 1604.45 | AG6: 1916.62 | AH6: 2057.92
E7: Germany | H7: ='Attached-IRENA2024 report'!J24 -> 730.77006 | O7: =AVERAGE('Attached-DIB_GNESTE_Solar_Power'!X89:X90) -> 757.7542
E8: United Kingdom | H8: ='Attached-IRENA2024 report'!J26 -> 932.69058
E9: Portugal | H9: ='Attached-IRENA2024 report'!J28 -> 723.26964
E10: France | H10: ='Attached-IRENA2024 report'!J30 -> 954.78012 | I10: {='Attached-IEA2020Projected Costs'!K21:M21} -> 718.7719 | J10: 732.59571 | K10: 742.79475 | L10: =AVERAGE('Attached-IEA2020Projected Costs'!K19:K20) -> 1293.7894 | M10: =AVERAGE('Attached-IEA2020Projected Costs'!L19:L20) -> 1318.6723 | N10: =AVERAGE('Attached-IEA2020Projected Costs'!M19:M20) -> 1337.0305 | V10: BRZ
E11: Italy | H11: ='Attached-IRENA2024 report'!J32 -> 821.34079 | I11: =AVERAGE('Attached-IEA2020Projected Costs'!K31:K32) -> 844.08816 | J11: =AVERAGE('Attached-IEA2020Projected Costs'!L31:L32) -> 860.32211 | K11: =AVERAGE('Attached-IEA2020Projected Costs'!M31:M32) -> 872.29933 | L11: =AVERAGE('Attached-IEA2020Projected Costs'!K26:K30) -> 1347.0298 | M11: =AVERAGE('Attached-IEA2020Projected Costs'!L26:L30) -> 1372.9366 | N11: =AVERAGE('Attached-IEA2020Projected Costs'!M26:M30) -> 1392.0503 | X11: Stated Policies (STEPS) | AD11: Announced Pledges (APS)
E12: Spain | H12: ='Attached-IRENA2024 report'!J57 -> 670.76717 | V12: 2023 | X12: 2030 | Y12: 2035 | Z12: 2040 | AA12: 2045 | AB12: 2050 | AD12: 2030 | AE12: 2035 | AF12: 2040 | AG12: 2045 | AH12: 2050
E13: Turkey | H13: ='Attached-IRENA2024 report'!J58 -> 715.36 | V13: 41.48 | X13: 91.81 | Y13: 106.1 | Z13: 120.79 | AA13: 135.53 | AB13: 150.96 | AD13: 135.34 | AE13: 175.49 | AF13: 201.5 | AG13: 223.35 | AH13: 245.87
E14: Hungary | H14: ='Attached-IRENA2024 report'!J62 -> 1078 | I14: ='Attached-IEA2020Projected Costs'!K25 -> 978.03747 | J14: ='Attached-IEA2020Projected Costs'!L25 -> 996.84761 | K14: ='Attached-IEA2020Projected Costs'!M25 -> 1010.7255 | L14: =AVERAGE('Attached-IEA2020Projected Costs'!K22:K24) -> 1445.272 | M14: =AVERAGE('Attached-IEA2020Projected Costs'!L22:L24) -> 1473.0682 | N14: =AVERAGE('Attached-IEA2020Projected Costs'!M22:M24) -> 1493.5759
E15: Belgium | H15: ='Attached-IRENA2024 report'!J63 -> 965 | I15: ='Attached-IEA2020Projected Costs'!K12 -> 1006.2807 | J15: ='Attached-IEA2020Projected Costs'!L12 -> 1025.634 | K15: ='Attached-IEA2020Projected Costs'!M12 -> 1039.9126 | L15: =AVERAGE('Attached-IEA2020Projected Costs'!K9:K11) -> 1419.3349 | M15: =AVERAGE('Attached-IEA2020Projected Costs'!L9:L11) -> 1446.6323 | N15: =AVERAGE('Attached-IEA2020Projected Costs'!M9:M11) -> 1466.772
E16: Cyprus | H16: ='Attached-IRENA2024 report'!J64 -> 854 | V16: EU-27
E17: Slovakia | H17: ='Attached-IRENA2024 report'!J65 -> 844 | X17: Stated Policies (STEPS) | AD17: Announced Pledges (APS)
E18: Romania | H18: ='Attached-IRENA2024 report'!J67 -> 743 | V18: 2023 | X18: 2030 | Y18: 2035 | Z18: 2040 | AA18: 2045 | AB18: 2050 | AD18: 2030 | AE18: 2035 | AF18: 2040 | AG18: 2045 | AH18: 2050
E19: Latvia | H19: ='Attached-IRENA2024 report'!J68 -> 716 | V19: 266.93 | X19: 646.76 | Y19: 870.02 | Z19: 991.11 | AA19: 1055.84 | AB19: 1078.1 | AD19: 746.62 | AE19: 967.2 | AF19: 1050.68 | AG19: 1081.83 | AH19: 1091.41
E20: Estonia | H20: ='Attached-IRENA2024 report'!J69 -> 705
E21: Poland | H21: ='Attached-IRENA2024 report'!J70 -> 700
E22: Ireland | H22: ='Attached-IRENA2024 report'!J71 -> 686 | V22: Russia
E23: Luxembourg | H23: ='Attached-IRENA2024 report'!J72 -> 684 | X23: Stated Policies (STEPS) | AD23: Announced Pledges (APS)
E24: Austria | H24: ='Attached-IRENA2024 report'!J73 -> 678 | I24: ='Attached-IEA2020Projected Costs'!K6 -> 729.55348 | J24: ='Attached-IEA2020Projected Costs'!L6 -> 743.58464 | K24: ='Attached-IEA2020Projected Costs'!M6 -> 753.93667 | L24: ='Attached-IEA2020Projected Costs'!K6 -> 729.55348 | M24: ='Attached-IEA2020Projected Costs'!L6 -> 743.58464 | N24: ='Attached-IEA2020Projected Costs'!M6 -> 753.93667 | V24: 2023 | X24: 2030 | Y24: 2035 | Z24: 2040 | AA24: 2045 | AB24: 2050 | AD24: 2030 | AE24: 2035 | AF24: 2040 | AG24: 2045 | AH24: 2050
E25: Czech Republic | H25: ='Attached-IRENA2024 report'!J74 -> 663 | V25: 2.13 | X25: 4.14 | Y25: 4.94 | Z25: 6.01 | AA25: 7.15 | AB25: 8.41 | AD25: 5.49 | AE25: 8.85 | AF25: 12.61 | AG25: 16.55 | AH25: 19.87
E26: Bulgaria | H26: ='Attached-IRENA2024 report'!J75 -> 659
E27: Denmark | I27: =AVERAGE('Attached-IEA2020Projected Costs'!K17:K18) -> 587.43464 | J27: =AVERAGE('Attached-IEA2020Projected Costs'!L17:L18) -> 598.7325 | K27: =AVERAGE('Attached-IEA2020Projected Costs'!M17:M18) -> 607.06792 | L27: =AVERAGE('Attached-IEA2020Projected Costs'!K15:K16) -> 1026.7533 | M27: =AVERAGE('Attached-IEA2020Projected Costs'!L15:L16) -> 1046.5004 | N27: =AVERAGE('Attached-IEA2020Projected Costs'!M15:M16) -> 1061.0695
E28: Norway | L28: ='Attached-IEA2020Projected Costs'!K40 -> 998.35392 | M28: ='Attached-IEA2020Projected Costs'!L40 -> 1017.5548 | N28: ='Attached-IEA2020Projected Costs'!M40 -> 1031.721 | V28: CN
E29: Croatia | X29: Stated Policies (STEPS) | AD29: Announced Pledges (APS)
D30: South America | E30: Chile | H30: ='Attached-IRENA2024 report'!J50 -> 953.80679 | V30: 2023 | X30: 2030 | Y30: 2035 | Z30: 2040 | AA30: 2045 | AB30: 2050 | AD30: 2030 | AE30: 2035 | AF30: 2040 | AG30: 2045 | AH30: 2050
E31: Argentina | H31: ='Attached-IRENA2024 report'!J53 -> 830 | V31: 688.24 | X31: 3263.4 | Y31: 5343.62 | Z31: 7290.94 | AA31: 8887.57 | AB31: 9432.63 | AD31: 3315.59 | AE31: 5433.22 | AF31: 7415.35 | AG31: 9040.46 | AH31: 9597.53
E32: Brazil | F32: =Attached_WEO2023!B18 -> 730 | G32: =Attached_WEO2023!F18 -> 560 | H32: ='Attached-IRENA2024 report'!J48 -> 726.98559 | I32: ='Attached-IEA2020Projected Costs'!K60 -> 1215.2033 | J32: ='Attached-IEA2020Projected Costs'!L60 -> 1238.5747 | K32: ='Attached-IEA2020Projected Costs'!M60 -> 1255.8179 | O32: ='Attached-DIB_GNESTE_Solar_Power'!V134 -> 1382.1652
E33: South America | O33: ='Attached-DIB_GNESTE_Solar_Power'!AA338 -> 819.85934
D34: North America | E34: United States | F34: =Attached_WEO2023!B13 -> 1110 | G34: =Attached_WEO2023!F13 -> 3460 | H34: ='Attached-IRENA2024 report'!J42 -> 1108.5304 | I34: =AVERAGE('Attached-IEA2020Projected Costs'!K51:K55) -> 1087.637 | J34: =AVERAGE('Attached-IEA2020Projected Costs'!L51:L55) -> 1108.555 | K34: =AVERAGE('Attached-IEA2020Projected Costs'!M51:M55) -> 1123.9881 | L34: =AVERAGE('Attached-IEA2020Projected Costs'!K41:K50) -> 1789.2317 | M34: =AVERAGE('Attached-IEA2020Projected Costs'!L41:L50) -> 1823.6432 | N34: =AVERAGE('Attached-IEA2020Projected Costs'!M41:M50) -> 1849.0316 | O34: =AVERAGE('Attached-DIB_GNESTE_Solar_Power'!V15,'Attached-DIB_GNESTE_Solar_Power'!Z17:Z310,'Attached-DIB_GNESTE_Solar_Power'!AB313:AB315,'Attached-DIB_GNESTE_Solar_Power'!Z319,'Attached-DIB_GNESTE_Solar_Power'!X325,'Attached-DIB_GNESTE_Solar_Power'!Y326,'Attached-DIB_GNESTE_Solar_Power'!X331,'Attached-DIB_GNESTE_Solar_Power'!Y332) -> 1349.0303
E35: Canada | H35: ='Attached-IRENA2024 report'!J38 -> 1336.5221 | I35: =AVERAGE('Attached-IEA2020Projected Costs'!K13:K14) -> 1328.7693 | J35: =AVERAGE('Attached-IEA2020Projected Costs'!L13:L14) -> 1354.3249 | K35: =AVERAGE('Attached-IEA2020Projected Costs'!M13:M14) -> 1373.1795
E36: Mexico | H36: ='Attached-IRENA2024 report'!J40 -> 1049.5172 | O36: ='Attached-DIB_GNESTE_Solar_Power'!V137 -> 990.405 | V36: ASEAN
E37: North America | O37: ='Attached-DIB_GNESTE_Solar_Power'!AA337 -> 936.56791 | X37: Stated Policies (STEPS) | AD37: Announced Pledges (APS)
D38: Eurasia | E38: Russia | F38: =Attached_WEO2023!B15 -> 1250 | G38: =Attached_WEO2023!F15 -> 1610 | H38: ='Attached-IRENA2024 report'!J83 -> 1248 | O38: ='Attached-DIB_GNESTE_Solar_Power'!AA341 -> 787.78925 | V38: 2023 | X38: 2030 | Y38: 2035 | Z38: 2040 | AA38: 2045 | AB38: 2050 | AD38: 2030 | AE38: 2035 | AF38: 2040 | AG38: 2045 | AH38: 2050
D39: Asia Pacific | E39: Japan | F39: =Attached_WEO2023!B14 -> 1880 | G39: =Attached_WEO2023!F14 -> 1850 | H39: ='Attached-IRENA2024 report'!J15 -> 1875.2399 | I39: ='Attached-IEA2020Projected Costs'!K34 -> 2035.9917 | J39: ='Attached-IEA2020Projected Costs'!L34 -> 2075.149 | K39: ='Attached-IEA2020Projected Costs'!M34 -> 2104.0388 | L39: ='Attached-IEA2020Projected Costs'!K33 -> 2367.4727 | M39: ='Attached-IEA2020Projected Costs'!L33 -> 2413.0052 | N39: ='Attached-IEA2020Projected Costs'!M33 -> 2446.5985 | V39: 32.13 | X39: 82.67 | Y39: 150.99 | Z39: 236.9 | AA39: 319.85 | AB39: 408.09 | AD39: 165.71 | AE39: 368.34 | AF39: 669.78 | AG39: 898.17 | AH39: 1074.26
E40: China | F40: =Attached_WEO2023!B16 -> 670 | G40: =Attached_WEO2023!F16 -> 750 | H40: ='Attached-IRENA2024 report'!J11 -> 671.12616 | I40: ='Attached-IEA2020Projected Costs'!K61 -> 741.29534 | J40: ='Attached-IEA2020Projected Costs'!L61 -> 755.55232 | K40: ='Attached-IEA2020Projected Costs'!M61 -> 766.07096 | O40: ='Attached-DIB_GNESTE_Solar_Power'!AA342 -> 694.64666
E41: India | F41: =Attached_WEO2023!B17 -> 710 | G41: =Attached_WEO2023!F17 -> 780 | H41: ='Attached-IRENA2024 report'!J13 -> 711.32819 | I41: ='Attached-IEA2020Projected Costs'!K62 -> 638.03526 | J41: ='Attached-IEA2020Projected Costs'!L62 -> 650.30629 | K41: ='Attached-IEA2020Projected Costs'!M62 -> 659.35972 | O41: =AVERAGE('Attached-DIB_GNESTE_Solar_Power'!W25,'Attached-DIB_GNESTE_Solar_Power'!V135,'Attached-DIB_GNESTE_Solar_Power'!AA343) -> 670.57179
...

Sheet Summari-ForCount (Current&2050)
A1: *Priciple: Exclusive the duplicate records from WEO, IEA2020, IRENA from Data of Brief; Use the record of now (preferring latest year); if there are multiple records in a same reference (except those notifying maximum or minimum value), average them to represent the figure for this reference | BD1: Baseline PV generation mix (40% rooftop vs. 60% ground-mounted)
BD2: Capital expenditure ($ billion) | BE2: 2023 | BF2: SPS-2030 | BG2: SPS-2050 | BH2: APS-2030 | BI2: APS-2050 | BJ2: NZE-2030 | BK2: NZE-2050 | CA2: 2023 | CB2: SPS-2030 | CC2: SPS-2050 | CD2: APS-2030 | CE2: APS-2050 | CF2: NZE-2030 | CG2: NZE-2050 | CQ2: 2023 | CR2: SPS-2030 | CS2: SPS-2050 | CT2: APS-2030 | CU2: APS-2050
F3: WEO2024 (large, ground-mounted) | G3: WEO2024 (rooftop) | H3: IRENA2024 (large, ground-mounted) | I3: IEA2020 (large, ground-mounted, 3% disc-rate) | J3: IEA2020 (large, ground-mounted, 7% discount rate) | K3: IEA2020 (large, ground-mounted, 10% discount rate) | L3: IEA2020 (rooftop, 3% disc-rate) | M3: IEA2020 (rooftop, 7% discount rate) | N3: IEA2020 (rooftop, 10% discount rate) | O3: Hatton et al., 2024 (large, ground-mounted) | V3: USA | BD3: EUR | BE3: 301.27137 | BF3: 560.69282 | BG3: 800.1611 | BH3: 618.17907 | BI3: 851.92279 | BK3: - | BZ3: European Union | CA3: 299.49546 | CB3: 457.90608 | CC3: 558.4558 | CD3: 601.57043 | CE3: 778.20247 | CP3: EU-27 | CQ3: 299.49546 | CR3: 457.90608 | CS3: 558.4558 | CT3: 601.57043 | CU3: 778.20247
D4: Europe | E4: EU-27 | F4: =Attached_WEO2023!B12 -> 750 | G4: =Attached_WEO2023!F12 -> 990 | O4: =AVERAGE('Attached-DIB_GNESTE_Solar_Power'!W70:W74) -> 860.90269 | X4: Stated Policies (STEPS) | AD4: Announced Pledges (APS) | BD4: CSA | BE4: 52.237595 | BF4: 92.909724 | BG4: 155.5699 | BH4: 124.48575 | BI4: 261.60448 | BK4: - | BZ4: Brazil | CA4: 28.28936 | CB4: 38.19296 | CC4: 45.58992 | CD4: 63.077188 | CE4: 94.554539 | CP4: BR | CQ4: 28.28936 | CR4: 38.19296 | CS4: 45.58992 | CT4: 63.077188 | CU4: 94.554539
E5: Greece | H5: ='Attached-IRENA2024 report'!J20 -> 626.34564 | V5: 2023 | X5: 2030 | Y5: 2035 | Z5: 2040 | AA5: 2045 | AB5: 2050 | AD5: 2030 | AE5: 2035 | AF5: 2040 | AG5: 2045 | AH5: 2050 | BD5: NA | BE5: 301.64656 | BF5: 667.68688 | BG5: 1495.101 | BH5: 782.83762 | BI5: 1664.5941 | BK5: - | BZ5: United States | CA5: 351.043 | CB5: 719.98686 | CC5: 1690.1794 | CD5: 934.69399 | CE5: 1906.0387 | CP5: USA | CQ5: 351.043 | CR5: 719.98686 | CS5: 1690.1794 | CT5: 934.69399 | CU5: 1906.0387
E6: Netherlands | H6: ='Attached-IRENA2024 report'!J22 -> 753.19994 | I6: ='Attached-IEA2020Projected Costs'!K39 -> 819.39997 | J6: ='Attached-IEA2020Projected Costs'!L39 -> 835.15911 | K6: ='Attached-IEA2020Projected Costs'!M39 -> 846.78601 | L6: ='Attached-IEA2020Projected Costs'!K38 -> 858.48319 | M6: ='Attached-IEA2020Projected Costs'!L38 -> 874.994 | N6: ='Attached-IEA2020Projected Costs'!M38 -> 887.17547 | O6: =AVERAGE('Attached-DIB_GNESTE_Solar_Power'!V66:V68) -> 787.41448 | V6: 169.75 | X6: 563.37 | Y6: 912.72 | Z6: 1278.24 | AA6: 1626.29 | AB6: 1894.82 | AD6: 719.52 | AE6: 1210.5 | AF6: 1604.45 | AG6: 1916.62 | AH6: 2057.92 | BD6: Eurasia | BE6: 7.6758419 | BF6: 18.507324 | BG6: 29.019717 | BH6: 21.637334 | BI6: 52.544319 | BK6: - | BZ6: Russia | CA6: 4.0683 | CB6: 5.0922 | CC6: 7.28306 | CD6: 7.7309207 | CE6: 18.493516 | CP6: RU | CQ6: 4.0683 | CR6: 5.0922 | CS6: 7.28306 | CT6: 7.7309207 | CU6: 18.493516
E7: Germany | H7: ='Attached-IRENA2024 report'!J24 -> 730.77006 | O7: =AVERAGE('Attached-DIB_GNESTE_Solar_Power'!X89:X90) -> 757.7542 | BD7: APJ | BE7: 1358.9988 | BF7: 3515.1532 | BG7: 7294.6065 | BH7: 3642.1984 | BI7: 7915.9966 | BK7: - | BZ7: China | CA7: 517.55648 | CB7: 1468.53 | CC7: 2980.7111 | CD7: 1503.0015 | CE7: 3089.986 | CP7: CN | CQ7: 517.55648 | CR7: 1468.53 | CS7: 2980.7111 | CT7: 1503.0015 | CU7: 3089.986
E8: United Kingdom | H8: ='Attached-IRENA2024 report'!J26 -> 932.69058 | BD8: ME | BE8: 10.803 | BF8: 43.156772 | BG8: 134.83278 | BH8: 49.969803 | BI8: 200.45331 | BK8: - | BZ8: India | CA8: 62.92728 | CB8: 151.22688 | CC8: 397.2898 | CD8: 162.88718 | CE8: 477.5424 | CP8: IN | CQ8: 62.92728 | CR8: 151.22688 | CS8: 397.2898 | CT8: 162.88718 | CU8: 477.5424
E9: Portugal | H9: ='Attached-IRENA2024 report'!J28 -> 723.26964 | BD9: AF | BE9: 27.9456 | BF9: 80.711933 | BG9: 217.87728 | BH9: 135.69041 | BI9: 425.57191 | BK9: - | BZ9: Japan | CA9: 205.28768 | CB9: 213.4673 | CC9: 203.0496 | CD9: 281.25833 | CE9: 334.70239 | CP9: JP | CQ9: 205.28768 | CR9: 213.4673 | CS9: 203.0496 | CT9: 281.25833 | CU9: 334.70239
E10: France | H10: ='Attached-IRENA2024 report'!J30 -> 954.78012 | I10: {='Attached-IEA2020Projected Costs'!K21:M21} -> 718.7719 | J10: 732.59571 | K10: 742.79475 | L10: =AVERAGE('Attached-IEA2020Projected Costs'!K19:K20) -> 1293.7894 | M10: =AVERAGE('Attached-IEA2020Projected Costs'!L19:L20) -> 1318.6723 | N10: =AVERAGE('Attached-IEA2020Projected Costs'!M19:M20) -> 1337.0305 | V10: BRZ | BD10: Global | BE10: 1809.9278 | BF10: 4335.5785 | BG10: 8749.8537 | BH10: 4684.3552 | BI10: 10011.42 | BJ10: 4759.1397 | BK10: 10532.937 | BZ10: Southeast Asia | CA10: 49.647637 | CB10: 94.233327 | CC10: 278.21787 | CD10: 151.00202 | CE10: 536.30875 | CP10: ASEAN | CQ10: 49.647637 | CR10: 94.233327 | CS10: 278.21787 | CT10: 151.00202 | CU10: 536.30875
E11: Italy | H11: ='Attached-IRENA2024 report'!J32 -> 821.34079 | I11: =AVERAGE('Attached-IEA2020Projected Costs'!K31:K32) -> 844.08816 | J11: =AVERAGE('Attached-IEA2020Projected Costs'!L31:L32) -> 860.32211 | K11: =AVERAGE('Attached-IEA2020Projected Costs'!M31:M32) -> 872.29933 | L11: =AVERAGE('Attached-IEA2020Projected Costs'!K26:K30) -> 1347.0298 | M11: =AVERAGE('Attached-IEA2020Projected Costs'!L26:L30) -> 1372.9366 | N11: =AVERAGE('Attached-IEA2020Projected Costs'!M26:M30) -> 1392.0503 | X11: Stated Policies (STEPS) | AD11: Announced Pledges (APS) | BD11: 50% rooftop, 50% ground-mounted
E12: Spain | H12: ='Attached-IRENA2024 report'!J57 -> 670.76717 | V12: 2023 | X12: 2030 | Y12: 2035 | Z12: 2040 | AA12: 2045 | AB12: 2050 | AD12: 2030 | AE12: 2035 | AF12: 2040 | AG12: 2045 | AH12: 2050 | BD12: EUR | BE12: 11.615989 | BF12: 21.618388 | BG12: 30.851462 | BH12: 23.834861 | BI12: 32.847215 | BK12: - | BM12: =BE3+BE12 -> 312.88736 | BN12: =BF3+BF12 -> 582.31121 | BO12: =BG3+BG12 -> 831.01256 | BP12: =BH3+BH12 -> 642.01393 | BQ12: =BI3+BI12 -> 884.77 | BR12: - | BS12: - | CP12: EU-27 | CQ12: =CA3+CA24 -> 308.30415 | CR12: =CB3+CB24 -> 472.1348 | CS12: =CC3+CC24 -> 576.7835 | CT12: =CD3+CD24 -> 619.26367 | CU12: =CE3+CE24 -> 801.09078
E13: Turkey | H13: ='Attached-IRENA2024 report'!J58 -> 715.36 | V13: 41.48 | X13: 91.81 | Y13: 106.1 | Z13: 120.79 | AA13: 135.53 | AB13: 150.96 | AD13: 135.34 | AE13: 175.49 | AF13: 201.5 | AG13: 223.35 | AH13: 245.87 | BD13: CSA | BE13: -2.7196991 | BF13: -4.8372536 | BG13: -8.0995944 | BH13: -6.4812286 | BI13: -13.620181 | BK13: - | BM13: =BE4+BE13 -> 49.517896 | BN13: =BF4+BF13 -> 88.072471 | BO13: =BG4+BG13 -> 147.47031 | BP13: =BH4+BH13 -> 118.00452 | BQ13: =BI4+BI13 -> 247.9843 | BR13: - | BS13: - | CP13: BR | CQ13: =CA4+CA25 -> 27.5842 | CR13: =CB4+CB25 -> 37.18305 | CS13: =CC4+CC25 -> 44.5332 | CT13: =CD4+CD25 -> 61.504883 | CU13: =CE4+CE25 -> 92.197608
E14: Hungary | H14: ='Attached-IRENA2024 report'!J62 -> 1078 | I14: ='Attached-IEA2020Projected Costs'!K25 -> 978.03747 | J14: ='Attached-IEA2020Projected Costs'!L25 -> 996.84761 | K14: ='Attached-IEA2020Projected Costs'!M25 -> 1010.7255 | L14: =AVERAGE('Attached-IEA2020Projected Costs'!K22:K24) -> 1445.272 | M14: =AVERAGE('Attached-IEA2020Projected Costs'!L22:L24) -> 1473.0682 | N14: =AVERAGE('Attached-IEA2020Projected Costs'!M22:M24) -> 1493.5759 | BD14: NA | BE14: 20.053988 | BF14: 44.388986 | BG14: 99.396918 | BH14: 52.044407 | BI14: 110.66512 | BK14: - | BM14: =BE5+BE14 -> 321.70055 | BN14: =BF5+BF14 -> 712.07586 | BO14: =BG5+BG14 -> 1594.4979 | BP14: =BH5+BH14 -> 834.88202 | BQ14: =BI5+BI14 -> 1775.2592 | BR14: - | BS14: - | CP14: USA | CQ14: =CA5+CA26 -> 391.27375 | CR14: =CB5+CB26 -> 802.80225 | CS14: =CC5+CC26 -> 1885.3459 | CT14: =CD5+CD26 -> 1041.8132 | CU14: =CE5+CE26 -> 2124.4774
E15: Belgium | H15: ='Attached-IRENA2024 report'!J63 -> 965 | I15: ='Attached-IEA2020Projected Costs'!K12 -> 1006.2807 | J15: ='Attached-IEA2020Projected Costs'!L12 -> 1025.634 | K15: ='Attached-IEA2020Projected Costs'!M12 -> 1039.9126 | L15: =AVERAGE('Attached-IEA2020Projected Costs'!K9:K11) -> 1419.3349 | M15: =AVERAGE('Attached-IEA2020Projected Costs'!L9:L11) -> 1446.6323 | N15: =AVERAGE('Attached-IEA2020Projected Costs'!M9:M11) -> 1466.772 | BD15: Eurasia | BE15: 0.45185968 | BF15: 1.0894849 | BG15: 1.708326 | BH15: 1.2737416 | BI15: 3.0931668 | BK15: - | BM15: =BE6+BE15 -> 8.1277016 | BN15: =BF6+BF15 -> 19.596809 | BO15: =BG6+BG15 -> 30.728043 | BP15: =BH6+BH15 -> 22.911075 | BQ15: =BI6+BI15 -> 55.637486 | BR15: - | BS15: - | CP15: RU | CQ15: =CA6+CA27 -> 4.1748 | CR15: =CB6+CB27 -> 5.2371 | CS15: =CC6+CC27 -> 7.4849 | CT15: =CD6+CD27 -> 7.9333008 | CU15: =CE6+CE27 -> 18.977639
E16: Cyprus | H16: ='Attached-IRENA2024 report'!J64 -> 854 | V16: EU-27 | BD16: APJ | BE16: 42.602525 | BF16: 110.19465 | BG16: 228.6747 | BH16: 114.17732 | BI16: 248.15433 | BK16: - | BM16: =BE7+BE16 -> 1401.6014 | BN16: =BF7+BF16 -> 3625.3478 | BO16: =BG7+BG16 -> 7523.2812 | BP16: =BH7+BH16 -> 3756.3758 | BQ16: =BI7+BI16 -> 8164.1509 | BR16: - | BS16: - | CP16: CN | CQ16: =CA7+CA28 -> 523.0624 | CR16: =CB7+CB28 -> 1484.847 | CS16: =CC7+CC28 -> 3018.4416 | CT16: =CD7+CD28 -> 1518.9909 | CU16: =CE7+CE28 -> 3122.8582
E17: Slovakia | H17: ='Attached-IRENA2024 report'!J65 -> 844 | X17: Stated Policies (STEPS) | AD17: Announced Pledges (APS) | BD17: ME | BE17: 0.554 | BF17: 2.2131678 | BG17: 6.16882 | BH17: 2.562554 | BI17: 10.279657 | BK17: - | BM17: =BE8+BE17 -> 11.357 | BN17: =BF8+BF17 -> 45.36994 | BO17: =BG8+BG17 -> 141.0016 | BP17: =BH8+BH17 -> 52.532357 | BQ17: =BI8+BI17 -> 210.73297 | BR17: - | BS17: - | CP17: IN | CQ17: =CA8+CA29 -> 63.4959 | CR17: =CB8+CB29 -> 152.7168 | CS17: =CC8+CC29 -> 400.148 | CT17: =CD8+CD29 -> 164.35906 | CU17: =CE8+CE29 -> 481.85754
E18: Romania | H18: ='Attached-IRENA2024 report'!J67 -> 743 | V18: 2023 | X18: 2030 | Y18: 2035 | Z18: 2040 | AA18: 2045 | AB18: 2050 | AD18: 2030 | AE18: 2035 | AF18: 2040 | AG18: 2045 | AH18: 2050 | BD18: AF | BE18: 0.9372 | BF18: 2.7068026 | BG18: 6.31047 | BH18: 4.5505929 | BI18: 14.272229 | BK18: - | BM18: =BE9+BE18 -> 28.8828 | BN18: =BF9+BF18 -> 83.418736 | BO18: =BG9+BG18 -> 224.18775 | BP18: =BH9+BH18 -> 140.241 | BQ18: =BI9+BI18 -> 439.84414 | BR18: - | BS18: - | CP18: JP | CQ18: =CA9+CA30 -> 204.9632 | CR18: =CB9+CB30 -> 213.97475 | CS18: =CC9+CC30 -> 204.10715 | CT18: =CD9+CD30 -> 280.81377 | CU18: =CE9+CE30 -> 334.17336
E19: Latvia | H19: ='Attached-IRENA2024 report'!J68 -> 716 | V19: 266.93 | X19: 646.76 | Y19: 870.02 | Z19: 991.11 | AA19: 1055.84 | AB19: 1078.1 | AD19: 746.62 | AE19: 967.2 | AF19: 1050.68 | AG19: 1081.83 | AH19: 1091.41 | BD19: Global | BE19: 115.27104 | BF19: 276.12518 | BG19: 557.26241 | BH19: 298.33814 | BI19: 637.60927 | BJ19: 303.10103 | BK19: 670.8238 | BM19: =BE10+BE19 -> 1925.1988 | BN19: =BF10+BF19 -> 4611.7037 | BO19: =BG10+BG19 -> 9307.1161 | BP19: =BH10+BH19 -> 4982.6933 | BQ19: =BI10+BI19 -> 10649.029 | BR19: =BJ10+BJ19 -> 5062.2407 | BS19: =BK10+BK19 -> 11203.761 | CP19: ASEAN | CQ19: =CA10+CA31 -> 49.970199 | CR19: =CB10+CB31 -> 94.845563 | CS19: =CC10+CC31 -> 280.02546 | CT19: =CD10+CD31 -> 151.98309 | CU19: =CE10+CE31 -> 539.79316
E20: Estonia | H20: ='Attached-IRENA2024 report'!J69 -> 705 | BD20: 60% rooftop, 40% ground-mounted
E21: Poland | H21: ='Attached-IRENA2024 report'!J70 -> 700 | BD21: EUR | BE21: 23.231978 | BF21: 43.236777 | BG21: 61.702925 | BH21: 47.669721 | BI21: 65.694431 | BK21: - | BM21: =BE3+BE21 -> 324.50335 | BN21: =BF3+BF21 -> 603.92959 | BO21: =BG3+BG21 -> 861.86403 | BP21: =BH3+BH21 -> 665.84879 | BQ21: =BI3+BI21 -> 917.61722 | BR21: - | BS21: - | CP21: EU-27 | CQ21: =CA3+CA34 -> 317.11284 | CR21: =CB3+CB34 -> 486.36352 | CS21: =CC3+CC34 -> 595.1112 | CT21: =CD3+CD34 -> 636.95692 | CU21: =CE3+CE34 -> 823.97909
E22: Ireland | H22: ='Attached-IRENA2024 report'!J71 -> 686 | V22: Russia | BD22: CSA | BE22: -5.4393983 | BF22: -9.6745073 | BG22: -16.199189 | BH22: -12.962457 | BI22: -27.240361 | BK22: - | BM22: =BE4+BE22 -> 46.798197 | BN22: =BF4+BF22 -> 83.235217 | BO22: =BG4+BG22 -> 139.37072 | BP22: =BH4+BH22 -> 111.5233 | BQ22: =BI4+BI22 -> 234.36412 | BR22: - | BS22: - | CP22: BR | CQ22: =CA4+CA35 -> 26.87904 | CR22: =CB4+CB35 -> 36.17314 | CS22: =CC4+CC35 -> 43.47648 | CT22: =CD4+CD35 -> 59.932578 | CU22: =CE4+CE35 -> 89.840676
E23: Luxembourg | H23: ='Attached-IRENA2024 report'!J72 -> 684 | X23: Stated Policies (STEPS) | AD23: Announced Pledges (APS) | BD23: NA | BE23: 40.107977 | BF23: 88.777972 | BG23: 198.79384 | BH23: 104.08881 | BI23: 221.33023 | BK23: - | BM23: =BE5+BE23 -> 341.75454 | BN23: =BF5+BF23 -> 756.46485 | BO23: =BG5+BG23 -> 1693.8949 | BP23: =BH5+BH23 -> 886.92643 | BQ23: =BI5+BI23 -> 1885.9244 | BR23: - | BS23: - | BZ23: 50-PCT | CP23: USA | CQ23: =CA5+CA36 -> 431.5045 | CR23: =CB5+CB36 -> 885.61764 | CS23: =CC5+CC36 -> 2080.5124 | CT23: =CD5+CD36 -> 1148.9324 | CU23: =CE5+CE36 -> 2342.9161
E24: Austria | H24: ='Attached-IRENA2024 report'!J73 -> 678 | I24: ='Attached-IEA2020Projected Costs'!K6 -> 729.55348 | J24: ='Attached-IEA2020Projected Costs'!L6 -> 743.58464 | K24: ='Attached-IEA2020Projected Costs'!M6 -> 753.93667 | L24: ='Attached-IEA2020Projected Costs'!K6 -> 729.55348 | M24: ='Attached-IEA2020Projected Costs'!L6 -> 743.58464 | N24: ='Attached-IEA2020Projected Costs'!M6 -> 753.93667 | V24: 2023 | X24: 2030 | Y24: 2035 | Z24: 2040 | AA24: 2045 | AB24: 2050 | AD24: 2030 | AE24: 2035 | AF24: 2040 | AG24: 2045 | AH24: 2050 | BD24: Eurasia | BE24: 0.90371937 | BF24: 2.1789698 | BG24: 3.4166519 | BH24: 2.5474831 | BI24: 6.1863336 | BK24: - | BM24: =BE6+BE24 -> 8.5795613 | BN24: =BF6+BF24 -> 20.686294 | BO24: =BG6+BG24 -> 32.436369 | BP24: =BH6+BH24 -> 24.184817 | BQ24: =BI6+BI24 -> 58.730652 | BR24: - | BS24: - | BZ24: European Union | CA24: 8.80869 | CB24: 14.22872 | CC24: 18.3277 | CD24: 17.693248 | CE24: 22.888308 | CP24: RU | CQ24: =CA6+CA37 -> 4.2813 | CR24: =CB6+CB37 -> 5.382 | CS24: =CC6+CC37 -> 7.68674 | CT24: =CD6+CD37 -> 8.1356809 | CU24: =CE6+CE37 -> 19.461763
E25: Czech Republic | H25: ='Attached-IRENA2024 report'!J74 -> 663 | V25: 2.13 | X25: 4.14 | Y25: 4.94 | Z25: 6.01 | AA25: 7.15 | AB25: 8.41 | AD25: 5.49 | AE25: 8.85 | AF25: 12.61 | AG25: 16.55 | AH25: 19.87 | BD25: APJ | BE25: 85.205049 | BF25: 220.3893 | BG25: 457.34941 | BH25: 228.35465 | BI25: 496.30865 | BK25: - | BM25: =BE7+BE25 -> 1444.2039 | BN25: =BF7+BF25 -> 3735.5425 | BO25: =BG7+BG25 -> 7751.9559 | BP25: =BH7+BH25 -> 3870.5531 | BQ25: =BI7+BI25 -> 8412.3052 | BR25: - | BS25: - | BZ25: Brazil | CA25: -0.70516 | CB25: -1.00991 | CC25: -1.05672 | CD25: -1.5723053 | CE25: -2.3569313 | CP25: CN | CQ25: =CA7+CA38 -> 528.56832 | CR25: =CB7+CB38 -> 1501.164 | CS25: =CC7+CC38 -> 3056.1721 | CT25: =CD7+CD38 -> 1534.9803 | CU25: =CE7+CE38 -> 3155.7304
E26: Bulgaria | H26: ='Attached-IRENA2024 report'!J75 -> 659 | BD26: ME | BE26: 1.108 | BF26: 4.4263356 | BG26: 12.33764 | BH26: 5.125108 | BI26: 20.559314 | BK26: - | BM26: =BE8+BE26 -> 11.911 | BN26: =BF8+BF26 -> 47.583108 | BO26: =BG8+BG26 -> 147.17042 | BP26: =BH8+BH26 -> 55.094911 | BQ26: =BI8+BI26 -> 221.01263 | BR26: - | BS26: - | BZ26: United States | CA26: 40.23075 | CB26: 82.81539 | CC26: 195.16646 | CD26: 107.11919 | CE26: 218.43867 | CP26: IN | CQ26: =CA8+CA39 -> 64.06452 | CR26: =CB8+CB39 -> 154.20672 | CS26: =CC8+CC39 -> 403.0062 | CT26: =CD8+CD39 -> 165.83093 | CU26: =CE8+CE39 -> 486.17269
E27: Denmark | I27: =AVERAGE('Attached-IEA2020Projected Costs'!K17:K18) -> 587.43464 | J27: =AVERAGE('Attached-IEA2020Projected Costs'!L17:L18) -> 598.7325 | K27: =AVERAGE('Attached-IEA2020Projected Costs'!M17:M18) -> 607.06792 | L27: =AVERAGE('Attached-IEA2020Projected Costs'!K15:K16) -> 1026.7533 | M27: =AVERAGE('Attached-IEA2020Projected Costs'!L15:L16) -> 1046.5004 | N27: =AVERAGE('Attached-IEA2020Projected Costs'!M15:M16) -> 1061.0695 | BD27: AF | BE27: 1.8744 | BF27: 5.4136053 | BG27: 12.62094 | BH27: 9.1011857 | BI27: 28.544458 | BK27: - | BM27: =BE9+BE27 -> 29.82 | BN27: =BF9+BF27 -> 86.125538 | BO27: =BG9+BG27 -> 230.49822 | BP27: =BH9+BH27 -> 144.79159 | BQ27: =BI9+BI27 -> 454.11637 | BR27: - | BS27: - | BZ27: Russia | CA27: 0.1065 | CB27: 0.1449 | CC27: 0.20184 | CD27: 0.20238012 | CE27: 0.48412346 | CP27: JP | CQ27: =CA9+CA40 -> 204.63872 | CR27: =CB9+CB40 -> 214.4822 | CS27: =CC9+CC40 -> 205.1647 | CT27: =CD9+CD40 -> 280.36921 | CU27: =CE9+CE40 -> 333.64432
E28: Norway | L28: ='Attached-IEA2020Projected Costs'!K40 -> 998.35392 | M28: ='Attached-IEA2020Projected Costs'!L40 -> 1017.5548 | N28: ='Attached-IEA2020Projected Costs'!M40 -> 1031.721 | V28: CN | BD28: Global | BE28: 230.54207 | BF28: 552.25036 | BG28: 1114.5248 | BH28: 596.67628 | BI28: 1275.2185 | BJ28: 606.20205 | BK28: 1341.6476 | BM28: =BE10+BE28 -> 2040.4698 | BN28: =BF10+BF28 -> 4887.8289 | BO28: =BG10+BG28 -> 9864.3785 | BP28: =BH10+BH28 -> 5281.0315 | BQ28: =BI10+BI28 -> 11286.638 | BR28: =BJ10+BJ28 -> 5365.3417 | BS28: =BK10+BK28 -> 11874.585 | BZ28: China | CA28: 5.50592 | CB28: 16.317 | CC28: 37.73052 | CD28: 15.989378 | CE28: 32.872191 | CP28: ASEAN | CQ28: =CA10+CA41 -> 50.292761 | CR28: =CB10+CB41 -> 95.457799 | CS28: =CC10+CC41 -> 281.83304 | CT28: =CD10+CD41 -> 152.96415 | CU28: =CE10+CE41 -> 543.27757
E29: Croatia | X29: Stated Policies (STEPS) | AD29: Announced Pledges (APS) | BD29: 70% rooftop, 30% ground-mounted | BZ29: India | CA29: 0.56862 | CB29: 1.48992 | CC29: 2.8582 | CD29: 1.4718721 | CE29: 4.3151422
D30: South America | E30: Chile | H30: ='Attached-IRENA2024 report'!J50 -> 953.80679 | V30: 2023 | X30: 2030 | Y30: 2035 | Z30: 2040 | AA30: 2045 | AB30: 2050 | AD30: 2030 | AE30: 2035 | AF30: 2040 | AG30: 2045 | AH30: 2050 | BD30: EUR | BE30: 34.847966 | BF30: 64.855165 | BG30: 92.554387 | BH30: 71.504582 | BI30: 98.541646 | BK30: - | BM30: =BE3+BE30 -> 336.11934 | BN30: =BF3+BF30 -> 625.54798 | BO30: =BG3+BG30 -> 892.71549 | BP30: =BH3+BH30 -> 689.68365 | BQ30: =BI3+BI30 -> 950.46444 | BR30: - | BS30: - | BZ30: Japan | CA30: -0.32448 | CB30: 0.50745 | CC30: 1.05755 | CD30: -0.44456005 | CE30: -0.52903434 | CP30: EU-27 | CQ30: =CA3+CA44 -> 325.92153 | CR30: =CB3+CB44 -> 500.59224 | CS30: =CC3+CC44 -> 613.4389 | CT30: =CD3+CD44 -> 654.65017 | CU30: =CE3+CE44 -> 846.8674
E31: Argentina | H31: ='Attached-IRENA2024 report'!J53 -> 830 | V31: 688.24 | X31: 3263.4 | Y31: 5343.62 | Z31: 7290.94 | AA31: 8887.57 | AB31: 9432.63 | AD31: 3315.59 | AE31: 5433.22 | AF31: 7415.35 | AG31: 9040.46 | AH31: 9597.53 | BD31: CSA | BE31: -8.1590974 | BF31: -14.511761 | BG31: -24.298783 | BH31: -19.443686 | BI31: -40.860542 | BK31: - | BM31: =BE4+BE31 -> 44.078497 | BN31: =BF4+BF31 -> 78.397963 | BO31: =BG4+BG31 -> 131.27112 | BP31: =BH4+BH31 -> 105.04207 | BQ31: =BI4+BI31 -> 220.74394 | BR31: - | BS31: - | BZ31: Southeast Asia | CA31: 0.32256186 | CB31: 0.61223613 | CC31: 1.807588 | CD31: 0.98106367 | CE31: 3.4844105 | CP31: BR | CQ31: =CA4+CA45 -> 26.17388 | CR31: =CB4+CB45 -> 35.16323 | CS31: =CC4+CC45 -> 42.41976 | CT31: =CD4+CD45 -> 58.360272 | CU31: =CE4+CE45 -> 87.483745
E32: Brazil | F32: =Attached_WEO2023!B18 -> 730 | G32: =Attached_WEO2023!F18 -> 560 | H32: ='Attached-IRENA2024 report'!J48 -> 726.98559 | I32: ='Attached-IEA2020Projected Costs'!K60 -> 1215.2033 | J32: ='Attached-IEA2020Projected Costs'!L60 -> 1238.5747 | K32: ='Attached-IEA2020Projected Costs'!M60 -> 1255.8179 | O32: ='Attached-DIB_GNESTE_Solar_Power'!V134 -> 1382.1652 | BD32: NA | BE32: 60.161965 | BF32: 133.16696 | BG32: 298.19075 | BH32: 156.13322 | BI32: 331.99535 | BK32: - | BM32: =BE5+BE32 -> 361.80853 | BN32: =BF5+BF32 -> 800.85383 | BO32: =BG5+BG32 -> 1793.2918 | BP32: =BH5+BH32 -> 938.97084 | BQ32: =BI5+BI32 -> 1996.5895 | BR32: - | BS32: - | CP32: USA | CQ32: =CA5+CA46 -> 471.73525 | CR32: =CB5+CB46 -> 968.43303 | CS32: =CC5+CC46 -> 2275.6788 | CT32: =CD5+CD46 -> 1256.0516 | CU32: =CE5+CE46 -> 2561.3547
E33: South America | O33: ='Attached-DIB_GNESTE_Solar_Power'!AA338 -> 819.85934 | BD33: Eurasia | BE33: 1.3555791 | BF33: 3.2684546 | BG33: 5.1249779 | BH33: 3.8212247 | BI33: 9.2795004 | BK33: - | BM33: =BE6+BE33 -> 9.0314209 | BN33: =BF6+BF33 -> 21.775779 | BO33: =BG6+BG33 -> 34.144695 | BP33: =BH6+BH33 -> 25.458558 | BQ33: =BI6+BI33 -> 61.823819 | BR33: - | BS33: - | CP33: RU | CQ33: =CA6+CA47 -> 4.3878 | CR33: =CB6+CB47 -> 5.5269 | CS33: =CC6+CC47 -> 7.88858 | CT33: =CD6+CD47 -> 8.338061 | CU33: =CE6+CE47 -> 19.945886
D34: North America | E34: United States | F34: =Attached_WEO2023!B13 -> 1110 | G34: =Attached_WEO2023!F13 -> 3460 | H34: ='Attached-IRENA2024 report'!J42 -> 1108.5304 | I34: =AVERAGE('Attached-IEA2020Projected Costs'!K51:K55) -> 1087.637 | J34: =AVERAGE('Attached-IEA2020Projected Costs'!L51:L55) -> 1108.555 | K34: =AVERAGE('Attached-IEA2020Projected Costs'!M51:M55) -> 1123.9881 | L34: =AVERAGE('Attached-IEA2020Projected Costs'!K41:K50) -> 1789.2317 | M34: =AVERAGE('Attached-IEA2020Projected Costs'!L41:L50) -> 1823.6432 | N34: =AVERAGE('Attached-IEA2020Projected Costs'!M41:M50) -> 1849.0316 | O34: =AVERAGE('Attached-DIB_GNESTE_Solar_Power'!V15,'Attached-DIB_GNESTE_Solar_Power'!Z17:Z310,'Attached-DIB_GNESTE_Solar_Power'!AB313:AB315,'Attached-DIB_GNESTE_Solar_Power'!Z319,'Attached-DIB_GNESTE_Solar_Power'!X325,'Attached-DIB_GNESTE_Solar_Power'!Y326,'Attached-DIB_GNESTE_Solar_Power'!X331,'Attached-DIB_GNESTE_Solar_Power'!Y332) -> 1349.0303 | BD34: APJ | BE34: 127.80757 | BF34: 330.58395 | BG34: 686.02411 | BH34: 342.53197 | BI34: 744.46298 | BK34: - | BM34: =BE7+BE34 -> 1486.8064 | BN34: =BF7+BF34 -> 3845.7371 | BO34: =BG7+BG34 -> 7980.6306 | BP34: =BH7+BH34 -> 3984.7304 | BQ34: =BI7+BI34 -> 8660.4595 | BR34: - | BS34: - | BZ34: 40-pct | CA34: 17.61738 | CB34: 28.45744 | CC34: 36.6554 | CD34: 35.386496 | CE34: 45.776616 | CP34: CN | CQ34: =CA7+CA48 -> 534.07424 | CR34: =CB7+CB48 -> 1517.481 | CS34: =CC7+CC48 -> 3093.9026 | CT34: =CD7+CD48 -> 1550.9697 | CU34: =CE7+CE48 -> 3188.6025
E35: Canada | H35: ='Attached-IRENA2024 report'!J38 -> 1336.5221 | I35: =AVERAGE('Attached-IEA2020Projected Costs'!K13:K14) -> 1328.7693 | J35: =AVERAGE('Attached-IEA2020Projected Costs'!L13:L14) -> 1354.3249 | K35: =AVERAGE('Attached-IEA2020Projected Costs'!M13:M14) -> 1373.1795 | BD35: ME | BE35: 1.662 | BF35: 6.6395034 | BG35: 18.50646 | BH35: 7.687662 | BI35: 30.838971 | BK35: - | BM35: =BE8+BE35 -> 12.465 | BN35: =BF8+BF35 -> 49.796275 | BO35: =BG8+BG35 -> 153.33924 | BP35: =BH8+BH35 -> 57.657465 | BQ35: =BI8+BI35 -> 231.29228 | BR35: - | BS35: - | CA35: -1.41032 | CB35: -2.01982 | CC35: -2.11344 | CD35: -3.1446106 | CE35: -4.7138626 | CP35: IN | CQ35: =CA8+CA49 -> 64.63314 | CR35: =CB8+CB49 -> 155.69664 | CS35: =CC8+CC49 -> 405.8644 | CT35: =CD8+CD49 -> 167.3028 | CU35: =CE8+CE49 -> 490.48783
E36: Mexico | H36: ='Attached-IRENA2024 report'!J40 -> 1049.5172 | O36: ='Attached-DIB_GNESTE_Solar_Power'!V137 -> 990.405 | V36: ASEAN | BD36: AF | BE36: 2.8116 | BF36: 8.1204079 | BG36: 18.93141 | BH36: 13.651779 | BI36: 42.816687 | BK36: - | BM36: =BE9+BE36 -> 30.7572 | BN36: =BF9+BF36 -> 88.832341 | BO36: =BG9+BG36 -> 236.80869 | BP36: =BH9+BH36 -> 149.34218 | BQ36: =BI9+BI36 -> 468.3886 | BR36: - | BS36: - | CA36: 80.4615 | CB36: 165.63078 | CC36: 390.33292 | CD36: 214.23837 | CE36: 436.87735 | CP36: JP | CQ36: =CA9+CA50 -> 204.31424 | CR36: =CB9+CB50 -> 214.98965 | CS36: =CC9+CC50 -> 206.22225 | CT36: =CD9+CD50 -> 279.92465 | CU36: =CE9+CE50 -> 333.11529
E37: North America | O37: ='Attached-DIB_GNESTE_Solar_Power'!AA337 -> 936.56791 | X37: Stated Policies (STEPS) | AD37: Announced Pledges (APS) | BD37: Global | BE37: 345.81311 | BF37: 828.37554 | BG37: 1671.7872 | BH37: 895.01442 | BI37: 1912.8278 | BJ37: 909.30308 | BK37: 2012.4714 | BM37: =BE10+BE37 -> 2155.7409 | BN37: =BF10+BF37 -> 5163.954 | BO37: =BG10+BG37 -> 10421.641 | BP37: =BH10+BH37 -> 5579.3696 | BQ37: =BI10+BI37 -> 11924.247 | BR37: =BJ10+BJ37 -> 5668.4427 | BS37: =BK10+BK37 -> 12545.409 | CA37: 0.213 | CB37: 0.2898 | CC37: 0.40368 | CD37: 0.40476024 | CE37: 0.96824691 | CP37: ASEAN | CQ37: =CA10+CA51 -> 50.615323 | CR37: =CB10+CB51 -> 96.070036 | CS37: =CC10+CC51 -> 283.64063 | CT37: =CD10+CD51 -> 153.94522 | CU37: =CE10+CE51 -> 546.76199
D38: Eurasia | E38: Russia | F38: =Attached_WEO2023!B15 -> 1250 | G38: =Attached_WEO2023!F15 -> 1610 | H38: ='Attached-IRENA2024 report'!J83 -> 1248 | O38: ='Attached-DIB_GNESTE_Solar_Power'!AA341 -> 787.78925 | V38: 2023 | X38: 2030 | Y38: 2035 | Z38: 2040 | AA38: 2045 | AB38: 2050 | AD38: 2030 | AE38: 2035 | AF38: 2040 | AG38: 2045 | AH38: 2050 | BD38: 80% rooftop, 20% ground-mounted | CA38: 11.01184 | CB38: 32.634 | CC38: 75.46104 | CD38: 31.978756 | CE38: 65.744382
D39: Asia Pacific | E39: Japan | F39: =Attached_WEO2023!B14 -> 1880 | G39: =Attached_WEO2023!F14 -> 1850 | H39: ='Attached-IRENA2024 report'!J15 -> 1875.2399 | I39: ='Attached-IEA2020Projected Costs'!K34 -> 2035.9917 | J39: ='Attached-IEA2020Projected Costs'!L34 -> 2075.149 | K39: ='Attached-IEA2020Projected Costs'!M34 -> 2104.0388 | L39: ='Attached-IEA2020Projected Costs'!K33 -> 2367.4727 | M39: ='Attached-IEA2020Projected Costs'!L33 -> 2413.0052 | N39: ='Attached-IEA2020Projected Costs'!M33 -> 2446.5985 | V39: 32.13 | X39: 82.67 | Y39: 150.99 | Z39: 236.9 | AA39: 319.85 | AB39: 408.09 | AD39: 165.71 | AE39: 368.34 | AF39: 669.78 | AG39: 898.17 | AH39: 1074.26 | BD39: EUR | BE39: 46.463955 | BF39: 86.473553 | BG39: 123.40585 | BH39: 95.339442 | BI39: 131.38886 | BK39: - | BM39: =BE3+BE39 -> 347.73533 | BN39: =BF3+BF39 -> 647.16637 | BO39: =BG3+BG39 -> 923.56695 | BP39: =BH3+BH39 -> 713.51851 | BQ39: =BI3+BI39 -> 983.31165 | BR39: - | BS39: - | CA39: 1.13724 | CB39: 2.97984 | CC39: 5.7164 | CD39: 2.9437443 | CE39: 8.6302844 | CP39: EU-27 | CQ39: =CA3+CA54 -> 334.73022 | CR39: =CB3+CB54 -> 514.82096 | CS39: =CC3+CC54 -> 631.7666 | CT39: =CD3+CD54 -> 672.34342 | CU39: =CE3+CE54 -> 869.75571
E40: China | F40: =Attached_WEO2023!B16 -> 670 | G40: =Attached_WEO2023!F16 -> 750 | H40: ='Attached-IRENA2024 report'!J11 -> 671.12616 | I40: ='Attached-IEA2020Projected Costs'!K61 -> 741.29534 | J40: ='Attached-IEA2020Projected Costs'!L61 -> 755.55232 | K40: ='Attached-IEA2020Projected Costs'!M61 -> 766.07096 | O40: ='Attached-DIB_GNESTE_Solar_Power'!AA342 -> 694.64666 | BD40: CSA | BE40: -10.878797 | BF40: -19.349015 | BG40: -32.398378 | BH40: -25.924914 | BI40: -54.480722 | BK40: - | BM40: =BE4+BE40 -> 41.358798 | BN40: =BF4+BF40 -> 73.56071 | BO40: =BG4+BG40 -> 123.17153 | BP40: =BH4+BH40 -> 98.560838 | BQ40: =BI4+BI40 -> 207.12376 | BR40: - | BS40: - | CA40: -0.64896 | CB40: 1.0149 | CC40: 2.1151 | CD40: -0.88912011 | CE40: -1.0580687 | CP40: BR | CQ40: =CA4+CA55 -> 25.46872 | CR40: =CB4+CB55 -> 34.15332 | CS40: =CC4+CC55 -> 41.36304 | CT40: =CD4+CD55 -> 56.787967 | CU40: =CE4+CE55 -> 85.126814
...

Sheet Summarize-ForReg(2030)
A1: *Priciple: Exclusive the duplicate records from WEO, IEA2020, IRENA from Data of Brief; Use the record of now (preferring latest year); if there are multiple records in a same reference (except those notifying maximum or minimum value), average them to represent the figure for this reference
F3: WEO2024 (large, ground-mounted) | G3: WEO2024 (rooftop) | H3: IRENA2024 (large, ground-mounted) | I3: IEA2020 (large, ground-mounted, 3% disc-rate) | J3: IEA2020 (large, ground-mounted, 7% discount rate) | K3: IEA2020 (large, ground-mounted, 10% discount rate) | L3: IEA2020 (rooftop, 3% disc-rate) | M3: IEA2020 (rooftop, 7% discount rate) | N3: IEA2020 (rooftop, 10% discount rate) | O3: Hatton et al., 2024 (large, ground-mounted) | V3: NA
D4: Europe | E4: EU-27 | F4: =Attached_WEO2023!B12 -> 750 | G4: =Attached_WEO2023!F12 -> 990 | O4: =AVERAGE('Attached-DIB_GNESTE_Solar_Power'!W70:W74) -> 860.90269 | X4: Stated Policies (STEPS) | AD4: Announced Pledges (APS)
E5: Greece | H5: ='Attached-IRENA2024 report'!J20 -> 626.34564 | V5: 2023 | X5: 2030 | Y5: 2035 | Z5: 2040 | AA5: 2045 | AB5: 2050 | AD5: 2030 | AE5: 2035 | AF5: 2040 | AG5: 2045 | AH5: 2050 | BD5: Cost components across | BE5: SPS | BK5: APS | BO5: NZE
E6: Netherlands | H6: ='Attached-IRENA2024 report'!J22 -> 753.19994 | I6: ='Attached-IEA2020Projected Costs'!K39 -> 819.39997 | J6: ='Attached-IEA2020Projected Costs'!L39 -> 835.15911 | K6: ='Attached-IEA2020Projected Costs'!M39 -> 846.78601 | L6: ='Attached-IEA2020Projected Costs'!K38 -> 858.48319 | M6: ='Attached-IEA2020Projected Costs'!L38 -> 874.994 | N6: ='Attached-IEA2020Projected Costs'!M38 -> 887.17547 | O6: =AVERAGE('Attached-DIB_GNESTE_Solar_Power'!V66:V68) -> 787.41448 | V6: 188.55 | X6: 608.6 | Y6: 973.35 | Z6: 1356.32 | AA6: 1718.79 | AB6: 1998.23 | AD6: 769.55 | AE6: 1311.5 | AF6: 1768.76 | AG6: 2146.99 | AH6: 2341.13 | BD6: geographies over years and scenarios | BE6: CAPEX ($/kW) | BH6: AOM ($/kW) | BK6: CAPEX | BM6: CAPEX ($/kW) | BO6: NZE-CAPEX ($/kW) | BR6: NZE-AOM ($/kW)
E7: Germany | H7: ='Attached-IRENA2024 report'!J24 -> 730.77006 | O7: =AVERAGE('Attached-DIB_GNESTE_Solar_Power'!X89:X90) -> 757.7542 | BK7: ($/kW)
E8: United Kingdom | H8: ='Attached-IRENA2024 report'!J26 -> 932.69058 | BE8: Present year | BF8: 2030 | BG8: 2050 | BH8: 2022 | BI8: 2030 | BJ8: 2050 | BK8: 2030 | BL8: 2050 | BM8: 2030 | BN8: 2050 | BP8: 2030 | BQ8: 2050 | BR8: 2030 | BS8: 2050
E9: Portugal | H9: ='Attached-IRENA2024 report'!J28 -> 723.26964 | BD9: Large,ground-mounted PV
E10: France | H10: ='Attached-IRENA2024 report'!J30 -> 954.78012 | I10: {='Attached-IEA2020Projected Costs'!K21:M21} -> 718.7719 | J10: 732.59571 | K10: 742.79475 | L10: =AVERAGE('Attached-IEA2020Projected Costs'!K19:K20) -> 1293.7894 | M10: =AVERAGE('Attached-IEA2020Projected Costs'!L19:L20) -> 1318.6723 | N10: =AVERAGE('Attached-IEA2020Projected Costs'!M19:M20) -> 1337.0305 | V10: CSA | BD10: EUR# | BE10: 801 | BF10: 596 | BG10: ='Summarize-ForReg(Current&2050)'!H60 -> 500.58529 | BK10: =K60 -> 565.8252 | BL10: ='Summarize-ForReg(Current&2050)'!K60 -> 485.9074
